2018-12-15 00:35:42,597 INFO: Microblog startup [in C:\Users\DELL\work\networks\app\__init__.py:44]
2018-12-15 00:43:05,680 INFO: Microblog startup [in C:\Users\DELL\work\networks\app\__init__.py:44]
2018-12-15 00:44:50,861 INFO: Microblog startup [in C:\Users\DELL\work\networks\app\__init__.py:44]
2018-12-15 00:45:23,319 INFO: Microblog startup [in C:\Users\DELL\work\networks\app\__init__.py:44]
2018-12-15 00:45:49,358 INFO: Microblog startup [in C:\Users\DELL\work\networks\app\__init__.py:44]
2018-12-15 00:46:23,659 INFO: Microblog startup [in C:\Users\DELL\work\networks\app\__init__.py:44]
2018-12-15 00:46:49,445 INFO: Microblog startup [in C:\Users\DELL\work\networks\app\__init__.py:44]
2018-12-15 00:47:38,745 INFO: Microblog startup [in C:\Users\DELL\work\networks\app\__init__.py:44]
2018-12-15 00:48:31,035 INFO: Microblog startup [in C:\Users\DELL\work\networks\app\__init__.py:44]
2018-12-15 00:51:30,396 INFO: Microblog startup [in C:\Users\DELL\work\networks\app\__init__.py:44]
2018-12-15 00:52:20,178 INFO: Microblog startup [in C:\Users\DELL\work\networks\app\__init__.py:44]
2018-12-15 00:55:16,695 INFO: Microblog startup [in C:\Users\DELL\work\networks\app\__init__.py:44]
2018-12-15 01:00:27,570 INFO: Microblog startup [in C:\Users\DELL\work\networks\app\__init__.py:44]
2018-12-15 01:01:20,097 INFO: Microblog startup [in C:\Users\DELL\work\networks\app\__init__.py:44]
2018-12-15 01:03:34,286 INFO: Microblog startup [in C:\Users\DELL\work\networks\app\__init__.py:44]
2018-12-15 01:06:30,704 INFO: Microblog startup [in C:\Users\DELL\work\networks\app\__init__.py:44]
2018-12-15 01:09:06,316 INFO: Microblog startup [in C:\Users\DELL\work\networks\app\__init__.py:44]
2018-12-15 01:10:07,172 INFO: Microblog startup [in C:\Users\DELL\work\networks\app\__init__.py:44]
2018-12-15 01:11:45,417 INFO: Microblog startup [in C:\Users\DELL\work\networks\app\__init__.py:44]
2018-12-15 01:18:23,924 INFO: Microblog startup [in C:\Users\DELL\work\networks\app\__init__.py:44]
2018-12-15 01:18:28,425 ERROR: Exception on /user/zhak [GET] [in c:\users\dell\work\networks\networks_venv\lib\site-packages\flask\app.py:1761]
Traceback (most recent call last):
  File "c:\users\dell\work\networks\networks_venv\lib\site-packages\flask\app.py", line 2292, in wsgi_app
    response = self.full_dispatch_request()
  File "c:\users\dell\work\networks\networks_venv\lib\site-packages\flask\app.py", line 1815, in full_dispatch_request
    rv = self.handle_user_exception(e)
  File "c:\users\dell\work\networks\networks_venv\lib\site-packages\flask\app.py", line 1718, in handle_user_exception
    reraise(exc_type, exc_value, tb)
  File "c:\users\dell\work\networks\networks_venv\lib\site-packages\flask\_compat.py", line 35, in reraise
    raise value
  File "c:\users\dell\work\networks\networks_venv\lib\site-packages\flask\app.py", line 1813, in full_dispatch_request
    rv = self.dispatch_request()
  File "c:\users\dell\work\networks\networks_venv\lib\site-packages\flask\app.py", line 1799, in dispatch_request
    return self.view_functions[rule.endpoint](**req.view_args)
  File "c:\users\dell\work\networks\networks_venv\lib\site-packages\flask_login\utils.py", line 261, in decorated_view
    return func(*args, **kwargs)
  File "C:\Users\DELL\work\networks\app\routes.py", line 81, in user
    return render_template('user.html', user=user, posts=posts)
  File "c:\users\dell\work\networks\networks_venv\lib\site-packages\flask\templating.py", line 135, in render_template
    context, ctx.app)
  File "c:\users\dell\work\networks\networks_venv\lib\site-packages\flask\templating.py", line 117, in _render
    rv = template.render(context)
  File "c:\users\dell\work\networks\networks_venv\lib\site-packages\jinja2\asyncsupport.py", line 76, in render
    return original_render(self, *args, **kwargs)
  File "c:\users\dell\work\networks\networks_venv\lib\site-packages\jinja2\environment.py", line 1008, in render
    return self.environment.handle_exception(exc_info, True)
  File "c:\users\dell\work\networks\networks_venv\lib\site-packages\jinja2\environment.py", line 780, in handle_exception
    reraise(exc_type, exc_value, tb)
  File "c:\users\dell\work\networks\networks_venv\lib\site-packages\jinja2\_compat.py", line 37, in reraise
    raise value.with_traceback(tb)
  File "C:\Users\DELL\work\networks\app\templates\user.html", line 1, in top-level template code
    {% extends "base.html" %}
  File "C:\Users\DELL\work\networks\app\templates\base.html", line 30, in top-level template code
    {% block content %}{% endblock %}
  File "C:\Users\DELL\work\networks\app\templates\user.html", line 6, in block "content"
    <!--{{ user.avatar(128) }}-->
  File "C:\Users\DELL\work\networks\app\models.py", line 43, in avatar
    md5(self.email.lower()).hexdigest(), urllib.urlencode({'d': default, 's': str(size)}))
TypeError: Unicode-objects must be encoded before hashing
2018-12-15 01:18:49,800 ERROR: Exception on /index [GET] [in c:\users\dell\work\networks\networks_venv\lib\site-packages\flask\app.py:1761]
Traceback (most recent call last):
  File "c:\users\dell\work\networks\networks_venv\lib\site-packages\flask\app.py", line 2292, in wsgi_app
    response = self.full_dispatch_request()
  File "c:\users\dell\work\networks\networks_venv\lib\site-packages\flask\app.py", line 1815, in full_dispatch_request
    rv = self.handle_user_exception(e)
  File "c:\users\dell\work\networks\networks_venv\lib\site-packages\flask\app.py", line 1718, in handle_user_exception
    reraise(exc_type, exc_value, tb)
  File "c:\users\dell\work\networks\networks_venv\lib\site-packages\flask\_compat.py", line 35, in reraise
    raise value
  File "c:\users\dell\work\networks\networks_venv\lib\site-packages\flask\app.py", line 1813, in full_dispatch_request
    rv = self.dispatch_request()
  File "c:\users\dell\work\networks\networks_venv\lib\site-packages\flask\app.py", line 1799, in dispatch_request
    return self.view_functions[rule.endpoint](**req.view_args)
  File "c:\users\dell\work\networks\networks_venv\lib\site-packages\flask_login\utils.py", line 261, in decorated_view
    return func(*args, **kwargs)
  File "C:\Users\DELL\work\networks\app\routes.py", line 31, in index
    posts=posts)
  File "c:\users\dell\work\networks\networks_venv\lib\site-packages\flask\templating.py", line 135, in render_template
    context, ctx.app)
  File "c:\users\dell\work\networks\networks_venv\lib\site-packages\flask\templating.py", line 117, in _render
    rv = template.render(context)
  File "c:\users\dell\work\networks\networks_venv\lib\site-packages\jinja2\asyncsupport.py", line 76, in render
    return original_render(self, *args, **kwargs)
  File "c:\users\dell\work\networks\networks_venv\lib\site-packages\jinja2\environment.py", line 1008, in render
    return self.environment.handle_exception(exc_info, True)
  File "c:\users\dell\work\networks\networks_venv\lib\site-packages\jinja2\environment.py", line 780, in handle_exception
    reraise(exc_type, exc_value, tb)
  File "c:\users\dell\work\networks\networks_venv\lib\site-packages\jinja2\_compat.py", line 37, in reraise
    raise value.with_traceback(tb)
  File "C:\Users\DELL\work\networks\app\templates\index.html", line 1, in top-level template code
    {% extends "base.html" %}
  File "C:\Users\DELL\work\networks\app\templates\base.html", line 30, in top-level template code
    {% block content %}{% endblock %}
  File "C:\Users\DELL\work\networks\app\templates\index.html", line 19, in block "content"
    {% include '_post.html' %}
  File "C:\Users\DELL\work\networks\app\templates\_post.html", line 3, in top-level template code
    <td><img src="{{ post.author.avatar(36) }}"></td>
  File "C:\Users\DELL\work\networks\app\models.py", line 43, in avatar
    md5(self.email.lower()).hexdigest(), urllib.urlencode({'d': default, 's': str(size)}))
TypeError: Unicode-objects must be encoded before hashing
